
<?xml version="1.0" encoding="utf-8"?>
<mujoco>
	<compiler angle="radian" coordinate="local" meshdir="../stls/fetch" texturedir="../textures"></compiler>
	<option timestep="0.002">
		<flag warmstart="enable"></flag>
	</option>

	<include file="shared.xml"></include>

	<worldbody>
		<geom name="floor0" pos="0.8 0.75 0" size="0.85 0.7 1" type="plane" condim="3" material="floor_mat"></geom>
		<body name="floor0" pos="0.8 0.75 0">
			<site name="target0" pos="0.67 0.23 0.401" size="0.08 0.1 0.001" rgba="1 0 0 1" type="box"></site>
		</body>

        	<body mocap="true" name="Robot1:mocap" pos="0 0 0">
		<geom conaffinity="0" contype="0" pos="0 0 0" rgba="0 0.5 0 0.7" size="0.005 0.005 0.005" type="box"></geom>
		<geom conaffinity="0" contype="0" pos="0 0 0" rgba="0 0.5 0 0.1" size="1 0.005 0.005" type="box"></geom>
		<geom conaffinity="0" contype="0" pos="0 0 0" rgba="0 0.5 0 0.1" size="0.005 1 0.001" type="box"></geom>
		<geom conaffinity="0" contype="0" pos="0 0 0" rgba="0 0.5 0 0.1" size="0.005 0.005 1" type="box"></geom>
	</body>
	<body childclass="Robot1:fetch" name="Robot1:base_link" pos="0.2869 0.2641 0">
		<joint armature="0.0001" axis="1 0 0" damping="1e+11" name="Robot1:slide0" pos="0 0 0" type="slide"></joint>
		<joint armature="0.0001" axis="0 1 0" damping="1e+11" name="Robot1:slide1" pos="0 0 0" type="slide"></joint>
		<joint armature="0.0001" axis="0 0 1" damping="1e+11" name="Robot1:slide2" pos="0 0 0" type="slide"></joint>
		<inertial diaginertia="1.2869 1.2236 0.9868" mass="70.1294" pos="-0.0036 0 0.0014" quat="0.7605 -0.0133 -0.0061 0.6491"></inertial>
		<geom mesh="Robot1:base_link" name="Robot1:base_link" material="Robot1:base_mat" class="Robot1:grey"></geom>
		<body name="Robot1:torso_lift_link" pos="-0.0869 0 0.3774">
			<inertial diaginertia="0.3365 0.3354 0.0943" mass="10.7796" pos="-0.0013 -0.0009 0.2935" quat="0.9993 -0.0006 0.0336 0.0185"></inertial>
			<joint axis="0 0 1" damping="1e+07" name="Robot1:torso_lift_joint" range="0.0386 0.3861" type="slide"></joint>
			<geom mesh="Robot1:torso_lift_link" name="Robot1:torso_lift_link" material="Robot1:torso_mat"></geom>
			<body name="Robot1:head_pan_link" pos="0.0531 0 0.603">
				<inertial diaginertia="0.0185 0.0128 0.0095" mass="2.2556" pos="0.0321 0.0161 0.039" quat="0.5148 0.5451 -0.453 0.4823"></inertial>
				<joint axis="0 0 1" name="Robot1:head_pan_joint" range="-1.57 1.57"></joint>
				<geom mesh="Robot1:head_pan_link" name="Robot1:head_pan_link" material="Robot1:head_mat" class="Robot1:grey"></geom>
				<body name="Robot1:head_tilt_link" pos="0.1425 0 0.058">
					<inertial diaginertia="0.0063 0.0059 0.0014" mass="0.9087" pos="0.0081 0.0025 0.0113" quat="0.6458 0.66 -0.274 0.2689"></inertial>
					<joint axis="0 1 0" damping="1000" name="Robot1:head_tilt_joint" range="-0.76 1.45" ref="0.06"></joint>
					<geom mesh="Robot1:head_tilt_link" name="Robot1:head_tilt_link" material="Robot1:head_mat" class="Robot1:blue"></geom>
					<body name="Robot1:head_camera_link" pos="0.055 0 0.0225">
						<inertial diaginertia="0 0 0" mass="0" pos="0.055 0 0.0225"></inertial>
						<body name="Robot1:head_camera_rgb_frame" pos="0 0.02 0">
							<inertial diaginertia="0 0 0" mass="0" pos="0 0.02 0"></inertial>
							<body name="Robot1:head_camera_rgb_optical_frame" pos="0 0 0" quat="0.5 -0.5 0.5 -0.5">
								<inertial diaginertia="0 0 0" mass="0" pos="0 0 0" quat="0.5 -0.5 0.5 -0.5"></inertial>
								<camera euler="3.1415 0 0" fovy="50" name="head_camera_rgb" pos="0 0 0"></camera>
							</body>
						</body>
						<body name="Robot1:head_camera_depth_frame" pos="0 0.045 0">
							<inertial diaginertia="0 0 0" mass="0" pos="0 0.045 0"></inertial>
							<body name="Robot1:head_camera_depth_optical_frame" pos="0 0 0" quat="0.5 -0.5 0.5 -0.5">
								<inertial diaginertia="0 0 0" mass="0" pos="0 0 0" quat="0.5 -0.5 0.5 -0.5"></inertial>
							</body>
						</body>
					</body>
				</body>
			</body>
			<body name="Robot1:shoulder_pan_link" pos="0.1195 0 0.3486">
				<inertial diaginertia="0.009 0.0086 0.0041" mass="2.5587" pos="0.0927 -0.0056 0.0564" quat="-0.1364 0.7624 -0.1562 0.613"></inertial>
				<joint axis="0 0 1" name="Robot1:shoulder_pan_joint" range="-1.6056 1.6056"></joint>
				<geom mesh="Robot1:shoulder_pan_link" name="Robot1:shoulder_pan_link" material="Robot1:arm_mat"></geom>
				<body name="Robot1:shoulder_lift_link" pos="0.117 0 0.06">
					<inertial diaginertia="0.0116 0.0112 0.0023" mass="2.6615" pos="0.1432 0.0072 -0.0001" quat="0.4382 0.4382 0.555 0.555"></inertial>
					<joint axis="0 1 0" name="Robot1:shoulder_lift_joint" range="-1.221 1.518"></joint>
					<geom mesh="Robot1:shoulder_lift_link" name="Robot1:shoulder_lift_link" material="Robot1:arm_mat" class="Robot1:blue"></geom>
					<body name="Robot1:upperarm_roll_link" pos="0.219 0 0">
						<inertial diaginertia="0.0047 0.0045 0.0019" mass="2.3311" pos="0.1165 0.0014 0" quat="-0.0136 0.707 0.0136 0.707"></inertial>
						<joint axis="1 0 0" limited="false" name="Robot1:upperarm_roll_joint"></joint>
						<geom mesh="Robot1:upperarm_roll_link" name="Robot1:upperarm_roll_link" material="Robot1:arm_mat"></geom>
						<body name="Robot1:elbow_flex_link" pos="0.133 0 0">
							<inertial diaginertia="0.0086 0.0084 0.002" mass="2.1299" pos="0.1279 0.0073 0" quat="0.4332 0.4332 0.5589 0.5589"></inertial>
							<joint axis="0 1 0" name="Robot1:elbow_flex_joint" range="-2.251 2.251"></joint>
							<geom mesh="Robot1:elbow_flex_link" name="Robot1:elbow_flex_link" material="Robot1:arm_mat" class="Robot1:blue"></geom>
							<body name="Robot1:forearm_roll_link" pos="0.197 0 0">
								<inertial diaginertia="0.0035 0.0031 0.0015" mass="1.6563" pos="0.1097 -0.0266 0" quat="-0.0715 0.7035 0.0715 0.7035"></inertial>
								<joint armature="2.7538" axis="1 0 0" damping="3.5247" frictionloss="0" limited="false" name="Robot1:forearm_roll_joint" stiffness="10"></joint>
								<geom mesh="Robot1:forearm_roll_link" name="Robot1:forearm_roll_link" material="Robot1:arm_mat"></geom>
								<body name="Robot1:wrist_flex_link" pos="0.1245 0 0">
									<inertial diaginertia="0.0042 0.0042 0.0018" mass="1.725" pos="0.0882 0.0009 -0.0001" quat="0.4895 0.4895 0.5103 0.5103"></inertial>
									<joint axis="0 1 0" name="Robot1:wrist_flex_joint" range="-2.16 2.16"></joint>
									<geom mesh="Robot1:wrist_flex_link" name="Robot1:wrist_flex_link" material="Robot1:arm_mat" class="Robot1:blue"></geom>
									<body name="Robot1:wrist_roll_link" pos="0.1385 0 0">
										<inertial diaginertia="0.0001 0.0001 0.0001" mass="0.1354" pos="0.0095 0.0004 -0.0002"></inertial>
										<joint axis="1 0 0" limited="false" name="Robot1:wrist_roll_joint"></joint>
										<geom mesh="Robot1:wrist_roll_link" name="Robot1:wrist_roll_link" material="Robot1:arm_mat"></geom>
										<body euler="0 0 0" name="Robot1:gripper_link" pos="0.1664 0 0">
											<inertial diaginertia="0.0024 0.0019 0.0013" mass="1.5175" pos="-0.09 -0.0001 -0.0017" quat="0 0.7071 0 0.7071"></inertial>
											<geom mesh="Robot1:gripper_link" name="Robot1:gripper_link" material="Robot1:gripper_mat"></geom>
											<body name="Robot1:gipper_camera_link" pos="0.055 0 0.0225">
												<body name="Robot1:gripper_camera_rgb_frame" pos="0 0.02 0">
													<body name="Robot1:gripper_camera_rgb_optical_frame" pos="0 0 0" quat="0.5 -0.5 0.5 -0.5">
														<camera euler="3.1415 0 0" fovy="50" name="gripper_camera_rgb" pos="0 0 0"></camera>
													</body>
												</body>
												<body name="Robot1:gripper_camera_depth_frame" pos="0 0.045 0">
													<body name="Robot1:gripper_camera_depth_optical_frame" pos="0 0 0" quat="0.5 -0.5 0.5 -0.5"></body>
												</body>
											</body>

											<body childclass="Robot1:fetchGripper" name="Robot1:r_gripper_finger_link" pos="0 0.0159 0">
												<inertial diaginertia="0.1 0.1 0.1" mass="4" pos="-0.01 0 0"></inertial>
												<joint axis="0 1 0" name="Robot1:r_gripper_finger_joint" range="0 0.05"></joint>
												<geom pos="0 -0.008 0" size="0.0385 0.007 0.0135" type="box" name="Robot1:r_gripper_finger_link" material="Robot1:gripper_finger_mat" condim="4" friction="1 0.05 0.01"></geom>
												<site name="Robot1:r_gripper_touch" pos="0 -0.008 0" rgba="0 0 0 0" type="box" size="0.0385 0.007 0.0135"></site>
											</body>
											<body childclass="Robot1:fetchGripper" name="Robot1:l_gripper_finger_link" pos="0 -0.0159 0">
												<inertial diaginertia="0.1 0.1 0.1" mass="4" pos="-0.01 0 0"></inertial>
												<joint axis="0 -1 0" name="Robot1:l_gripper_finger_joint" range="0 0.05"></joint>
												<geom pos="0 0.008 0" size="0.0385 0.007 0.0135" type="box" name="Robot1:l_gripper_finger_link" material="Robot1:gripper_finger_mat" condim="4" friction="1 0.05 0.01"></geom>
												<site name="Robot1:l_gripper_touch" pos="0 0.008 0" rgba="0 0 0 0" type="box" size="0.0385 0.007 0.0135"></site>
											</body>
											<site name="Robot1:grip" pos="0.02 0 0" rgba="0 0 0 0" size="0.02 0.02 0.02"></site>
										</body>
									</body>
								</body>
							</body>
						</body>
					</body>
				</body>
			</body>
		</body>
		<body name="Robot1:estop_link" pos="-0.1246 0.2389 0.3113" quat="0.7071 0.7071 0 0">
			<inertial diaginertia="0 0 0" mass="0.002" pos="0.0024 -0.0033 0.0067" quat="0.3774 -0.1814 0.1375 0.8977"></inertial>
			<geom mesh="Robot1:estop_link" rgba="0.8 0 0 1" name="Robot1:estop_link"></geom>
		</body>
		<body name="Robot1:laser_link" pos="0.235 0 0.2878" quat="0 1 0 0">
			<inertial diaginertia="0 0 0" mass="0.0083" pos="-0.0306 0.0007 0.0552" quat="0.5878 0.5378 -0.4578 0.3945"></inertial>
			<geom mesh="Robot1:laser_link" rgba="0.7922 0.8196 0.9333 1" name="Robot1:laser_link"></geom>
			<camera euler="1.55 -1.55 3.14" fovy="25" name="lidar" pos="0 0 0.02"></camera>
		</body>
		<body name="Robot1:torso_fixed_link" pos="-0.0869 0 0.3774">
			<inertial diaginertia="0.3865 0.3394 0.1009" mass="13.2775" pos="-0.0722 0.0057 0.2656" quat="0.9995 0.0249 0.0177 0.011"></inertial>
			<geom mesh="Robot1:torso_fixed_link" name="Robot1:torso_fixed_link" class="Robot1:blue"></geom>
		</body>
		<body name="Robot1:external_camera_body_0" pos="0 0 0" euler="0 0 0">
			<camera euler="0 0.75 1.57" fovy="43.3" name="external_camera_0" pos="1.3 0 1.2"></camera>
		</body>
		<body name="Robot1:external_camera_body_1" pos="0 0 0" euler="0 0 0">
			<camera pos="1.2 -1.2 1.2" xyaxes="0.91 0.42 0.0 -0.19 0.41 0.89" fovy="43.3" name="external_camera_1" ></camera>
		</body>
		<body name="Robot1:external_camera_body_2" pos="0 0 0" euler="0 0 0">
			<camera pos="1.2 1.2 1.2" xyaxes="-0.91 0.42 0.0 -0.19 -0.41 0.89" fovy="43.3" name="external_camera_2" ></camera>
		</body>
	</body>
</mujoco>

	<body mocap="true" name="Robot2:mocap" pos="0 0 0">
		<geom conaffinity="0" contype="0" pos="0 0 0" rgba="0 0.5 0 0.7" size="0.005 0.005 0.005" type="box"></geom>
		<geom conaffinity="0" contype="0" pos="0 0 0" rgba="0 0.5 0 0.1" size="1 0.005 0.005" type="box"></geom>
		<geom conaffinity="0" contype="0" pos="0 0 0" rgba="0 0.5 0 0.1" size="0.005 1 0.001" type="box"></geom>
		<geom conaffinity="0" contype="0" pos="0 0 0" rgba="0 0.5 0 0.1" size="0.005 0.005 1" type="box"></geom>
	</body>
	<body childclass="Robot2:fetch" name="Robot2:base_link" pos="0.2869 0.2641 0">
		<joint armature="0.0001" axis="1 0 0" damping="1e+11" name="Robot2:slide0" pos="0 0 0" type="slide"></joint>
		<joint armature="0.0001" axis="0 1 0" damping="1e+11" name="Robot2:slide1" pos="0 0 0" type="slide"></joint>
		<joint armature="0.0001" axis="0 0 1" damping="1e+11" name="Robot2:slide2" pos="0 0 0" type="slide"></joint>
		<inertial diaginertia="1.2869 1.2236 0.9868" mass="70.1294" pos="-0.0036 0 0.0014" quat="0.7605 -0.0133 -0.0061 0.6491"></inertial>
		<geom mesh="Robot2:base_link" name="Robot2:base_link" material="Robot2:base_mat" class="Robot2:grey"></geom>
		<body name="Robot2:torso_lift_link" pos="-0.0869 0 0.3774">
			<inertial diaginertia="0.3365 0.3354 0.0943" mass="10.7796" pos="-0.0013 -0.0009 0.2935" quat="0.9993 -0.0006 0.0336 0.0185"></inertial>
			<joint axis="0 0 1" damping="1e+07" name="Robot2:torso_lift_joint" range="0.0386 0.3861" type="slide"></joint>
			<geom mesh="Robot2:torso_lift_link" name="Robot2:torso_lift_link" material="Robot2:torso_mat"></geom>
			<body name="Robot2:head_pan_link" pos="0.0531 0 0.603">
				<inertial diaginertia="0.0185 0.0128 0.0095" mass="2.2556" pos="0.0321 0.0161 0.039" quat="0.5148 0.5451 -0.453 0.4823"></inertial>
				<joint axis="0 0 1" name="Robot2:head_pan_joint" range="-1.57 1.57"></joint>
				<geom mesh="Robot2:head_pan_link" name="Robot2:head_pan_link" material="Robot2:head_mat" class="Robot2:grey"></geom>
				<body name="Robot2:head_tilt_link" pos="0.1425 0 0.058">
					<inertial diaginertia="0.0063 0.0059 0.0014" mass="0.9087" pos="0.0081 0.0025 0.0113" quat="0.6458 0.66 -0.274 0.2689"></inertial>
					<joint axis="0 1 0" damping="1000" name="Robot2:head_tilt_joint" range="-0.76 1.45" ref="0.06"></joint>
					<geom mesh="Robot2:head_tilt_link" name="Robot2:head_tilt_link" material="Robot2:head_mat" class="Robot2:blue"></geom>
					<body name="Robot2:head_camera_link" pos="0.055 0 0.0225">
						<inertial diaginertia="0 0 0" mass="0" pos="0.055 0 0.0225"></inertial>
						<body name="Robot2:head_camera_rgb_frame" pos="0 0.02 0">
							<inertial diaginertia="0 0 0" mass="0" pos="0 0.02 0"></inertial>
							<body name="Robot2:head_camera_rgb_optical_frame" pos="0 0 0" quat="0.5 -0.5 0.5 -0.5">
								<inertial diaginertia="0 0 0" mass="0" pos="0 0 0" quat="0.5 -0.5 0.5 -0.5"></inertial>
								<camera euler="3.1415 0 0" fovy="50" name="head_camera_rgb" pos="0 0 0"></camera>
							</body>
						</body>
						<body name="Robot2:head_camera_depth_frame" pos="0 0.045 0">
							<inertial diaginertia="0 0 0" mass="0" pos="0 0.045 0"></inertial>
							<body name="Robot2:head_camera_depth_optical_frame" pos="0 0 0" quat="0.5 -0.5 0.5 -0.5">
								<inertial diaginertia="0 0 0" mass="0" pos="0 0 0" quat="0.5 -0.5 0.5 -0.5"></inertial>
							</body>
						</body>
					</body>
				</body>
			</body>
			<body name="Robot2:shoulder_pan_link" pos="0.1195 0 0.3486">
				<inertial diaginertia="0.009 0.0086 0.0041" mass="2.5587" pos="0.0927 -0.0056 0.0564" quat="-0.1364 0.7624 -0.1562 0.613"></inertial>
				<joint axis="0 0 1" name="Robot2:shoulder_pan_joint" range="-1.6056 1.6056"></joint>
				<geom mesh="Robot2:shoulder_pan_link" name="Robot2:shoulder_pan_link" material="Robot2:arm_mat"></geom>
				<body name="Robot2:shoulder_lift_link" pos="0.117 0 0.06">
					<inertial diaginertia="0.0116 0.0112 0.0023" mass="2.6615" pos="0.1432 0.0072 -0.0001" quat="0.4382 0.4382 0.555 0.555"></inertial>
					<joint axis="0 1 0" name="Robot2:shoulder_lift_joint" range="-1.221 1.518"></joint>
					<geom mesh="Robot2:shoulder_lift_link" name="Robot2:shoulder_lift_link" material="Robot2:arm_mat" class="Robot2:blue"></geom>
					<body name="Robot2:upperarm_roll_link" pos="0.219 0 0">
						<inertial diaginertia="0.0047 0.0045 0.0019" mass="2.3311" pos="0.1165 0.0014 0" quat="-0.0136 0.707 0.0136 0.707"></inertial>
						<joint axis="1 0 0" limited="false" name="Robot2:upperarm_roll_joint"></joint>
						<geom mesh="Robot2:upperarm_roll_link" name="Robot2:upperarm_roll_link" material="Robot2:arm_mat"></geom>
						<body name="Robot2:elbow_flex_link" pos="0.133 0 0">
							<inertial diaginertia="0.0086 0.0084 0.002" mass="2.1299" pos="0.1279 0.0073 0" quat="0.4332 0.4332 0.5589 0.5589"></inertial>
							<joint axis="0 1 0" name="Robot2:elbow_flex_joint" range="-2.251 2.251"></joint>
							<geom mesh="Robot2:elbow_flex_link" name="Robot2:elbow_flex_link" material="Robot2:arm_mat" class="Robot2:blue"></geom>
							<body name="Robot2:forearm_roll_link" pos="0.197 0 0">
								<inertial diaginertia="0.0035 0.0031 0.0015" mass="1.6563" pos="0.1097 -0.0266 0" quat="-0.0715 0.7035 0.0715 0.7035"></inertial>
								<joint armature="2.7538" axis="1 0 0" damping="3.5247" frictionloss="0" limited="false" name="Robot2:forearm_roll_joint" stiffness="10"></joint>
								<geom mesh="Robot2:forearm_roll_link" name="Robot2:forearm_roll_link" material="Robot2:arm_mat"></geom>
								<body name="Robot2:wrist_flex_link" pos="0.1245 0 0">
									<inertial diaginertia="0.0042 0.0042 0.0018" mass="1.725" pos="0.0882 0.0009 -0.0001" quat="0.4895 0.4895 0.5103 0.5103"></inertial>
									<joint axis="0 1 0" name="Robot2:wrist_flex_joint" range="-2.16 2.16"></joint>
									<geom mesh="Robot2:wrist_flex_link" name="Robot2:wrist_flex_link" material="Robot2:arm_mat" class="Robot2:blue"></geom>
									<body name="Robot2:wrist_roll_link" pos="0.1385 0 0">
										<inertial diaginertia="0.0001 0.0001 0.0001" mass="0.1354" pos="0.0095 0.0004 -0.0002"></inertial>
										<joint axis="1 0 0" limited="false" name="Robot2:wrist_roll_joint"></joint>
										<geom mesh="Robot2:wrist_roll_link" name="Robot2:wrist_roll_link" material="Robot2:arm_mat"></geom>
										<body euler="0 0 0" name="Robot2:gripper_link" pos="0.1664 0 0">
											<inertial diaginertia="0.0024 0.0019 0.0013" mass="1.5175" pos="-0.09 -0.0001 -0.0017" quat="0 0.7071 0 0.7071"></inertial>
											<geom mesh="Robot2:gripper_link" name="Robot2:gripper_link" material="Robot2:gripper_mat"></geom>
											<body name="Robot2:gipper_camera_link" pos="0.055 0 0.0225">
												<body name="Robot2:gripper_camera_rgb_frame" pos="0 0.02 0">
													<body name="Robot2:gripper_camera_rgb_optical_frame" pos="0 0 0" quat="0.5 -0.5 0.5 -0.5">
														<camera euler="3.1415 0 0" fovy="50" name="gripper_camera_rgb" pos="0 0 0"></camera>
													</body>
												</body>
												<body name="Robot2:gripper_camera_depth_frame" pos="0 0.045 0">
													<body name="Robot2:gripper_camera_depth_optical_frame" pos="0 0 0" quat="0.5 -0.5 0.5 -0.5"></body>
												</body>
											</body>

											<body childclass="Robot2:fetchGripper" name="Robot2:r_gripper_finger_link" pos="0 0.0159 0">
												<inertial diaginertia="0.1 0.1 0.1" mass="4" pos="-0.01 0 0"></inertial>
												<joint axis="0 1 0" name="Robot2:r_gripper_finger_joint" range="0 0.05"></joint>
												<geom pos="0 -0.008 0" size="0.0385 0.007 0.0135" type="box" name="Robot2:r_gripper_finger_link" material="Robot2:gripper_finger_mat" condim="4" friction="1 0.05 0.01"></geom>
												<site name="Robot2:r_gripper_touch" pos="0 -0.008 0" rgba="0 0 0 0" type="box" size="0.0385 0.007 0.0135"></site>
											</body>
											<body childclass="Robot2:fetchGripper" name="Robot2:l_gripper_finger_link" pos="0 -0.0159 0">
												<inertial diaginertia="0.1 0.1 0.1" mass="4" pos="-0.01 0 0"></inertial>
												<joint axis="0 -1 0" name="Robot2:l_gripper_finger_joint" range="0 0.05"></joint>
												<geom pos="0 0.008 0" size="0.0385 0.007 0.0135" type="box" name="Robot2:l_gripper_finger_link" material="Robot2:gripper_finger_mat" condim="4" friction="1 0.05 0.01"></geom>
												<site name="Robot2:l_gripper_touch" pos="0 0.008 0" rgba="0 0 0 0" type="box" size="0.0385 0.007 0.0135"></site>
											</body>
											<site name="Robot2:grip" pos="0.02 0 0" rgba="0 0 0 0" size="0.02 0.02 0.02"></site>
										</body>
									</body>
								</body>
							</body>
						</body>
					</body>
				</body>
			</body>
		</body>
		<body name="Robot2:estop_link" pos="-0.1246 0.2389 0.3113" quat="0.7071 0.7071 0 0">
			<inertial diaginertia="0 0 0" mass="0.002" pos="0.0024 -0.0033 0.0067" quat="0.3774 -0.1814 0.1375 0.8977"></inertial>
			<geom mesh="Robot2:estop_link" rgba="0.8 0 0 1" name="Robot2:estop_link"></geom>
		</body>
		<body name="Robot2:laser_link" pos="0.235 0 0.2878" quat="0 1 0 0">
			<inertial diaginertia="0 0 0" mass="0.0083" pos="-0.0306 0.0007 0.0552" quat="0.5878 0.5378 -0.4578 0.3945"></inertial>
			<geom mesh="Robot2:laser_link" rgba="0.7922 0.8196 0.9333 1" name="Robot2:laser_link"></geom>
			<camera euler="1.55 -1.55 3.14" fovy="25" name="lidar" pos="0 0 0.02"></camera>
		</body>
		<body name="Robot2:torso_fixed_link" pos="-0.0869 0 0.3774">
			<inertial diaginertia="0.3865 0.3394 0.1009" mass="13.2775" pos="-0.0722 0.0057 0.2656" quat="0.9995 0.0249 0.0177 0.011"></inertial>
			<geom mesh="Robot2:torso_fixed_link" name="Robot2:torso_fixed_link" class="Robot2:blue"></geom>
		</body>
		<body name="Robot2:external_camera_body_0" pos="0 0 0" euler="0 0 0">
			<camera euler="0 0.75 1.57" fovy="43.3" name="external_camera_0" pos="1.3 0 1.2"></camera>
		</body>
		<body name="Robot2:external_camera_body_1" pos="0 0 0" euler="0 0 0">
			<camera pos="1.2 -1.2 1.2" xyaxes="0.91 0.42 0.0 -0.19 0.41 0.89" fovy="43.3" name="external_camera_1" ></camera>
		</body>
		<body name="Robot2:external_camera_body_2" pos="0 0 0" euler="0 0 0">
			<camera pos="1.2 1.2 1.2" xyaxes="-0.91 0.42 0.0 -0.19 -0.41 0.89" fovy="43.3" name="external_camera_2" ></camera>
		</body>
	</body>
</mujoco>


<body pos="1.3 0.75 0.2" name="table0">
	<geom size="0.25 0.35 0.2" type="box" mass="2000" material="table_mat"></geom>
</body>



<body name="Small_Square" pos="0.0 0.0 0.0">
	<joint name="Small_Square:joint" type="free" damping="0.01"></joint>
	<geom size="0.1 0.1 0.1" type="box" condim="3" name="Small_Square" material="blue_mat" mass="2"></geom>
	<site name="Small_Square" pos="0 0 0" size="0.02 0.02 0.02" rgba="0.3 0.57 0.3 1" type="sphere"></site>
</body>




		<light directional="true" ambient="0.2 0.2 0.2" diffuse="0.8 0.8 0.8" specular="0.3 0.3 0.3" castshadow="false" pos="0 0 4" dir="0 0 -1" name="light0"></light>
	</worldbody>

	<actuator>
		<position ctrllimited="true" ctrlrange="0 0.2" joint="robot0:l_gripper_finger_joint" kp="30000" name="robot0:l_gripper_finger_joint" user="1"></position>
		<position ctrllimited="true" ctrlrange="0 0.2" joint="robot0:r_gripper_finger_joint" kp="30000" name="robot0:r_gripper_finger_joint" user="1"></position>
	</actuator>
</mujoco>
